{"stats": {"errors": 0, "failures": 1, "passes": 1, "skipped": 0, "encoding": "UTF-8", "total": 2}, "results": [{"classname": "index_test:HelperTest", "name": "test_p2pkh_address", "time": 0.0003974437713623047, "type": "success"}, {"classname": "index_test:HelperTest", "name": "test_p2sh_address", "time": 0.0002224445343017578, "type": "failure", "errtype": "builtins.AssertionError", "message": "None != '3CLoMMyuoDQTPRD3XYZtCvgvkadrAdvdXh'", "tb": "Traceback (most recent call last):\n  File \"/opt/conda/lib/python3.6/unittest/case.py\", line 59, in testPartExecutor\n    yield\n  File \"/opt/conda/lib/python3.6/unittest/case.py\", line 605, in run\n    testMethod()\n  File \"/home/sagi-test-pbc/advanced-scripting-jsong-pb-denver-070918/test/index_test.py\", line 16, in test_p2sh_address\n    self.assertEqual(h160_to_p2sh_address(h160, testnet=False), want)\n  File \"/opt/conda/lib/python3.6/unittest/case.py\", line 829, in assertEqual\n    assertion_func(first, second, msg=msg)\n  File \"/opt/conda/lib/python3.6/unittest/case.py\", line 822, in _baseAssertEqual\n    raise self.failureException(msg)\nAssertionError: None != '3CLoMMyuoDQTPRD3XYZtCvgvkadrAdvdXh'\n"}]}